2025-09-08 16:43:42,568 - MainProcess - ERROR - Util tele bot check dat:3 - Failed to send message: 'UtilTeleBotCheck' object has no attribute 'url'
2025-09-08 16:44:32,870 - MainProcess - ERROR - Util tele bot check data - Failed to send message: HTTPSConnectionPool(host='api.telegram.org', port=443): Max retries exceeded with url: /bot7608728463:AAGqqSN5brGw5BX9ZzQ7eD2SOERtfzs6Ylo/sendMessage (Caused by ConnectTimeoutError(<urllib3.connection.HTTPSConnection object at 0x0000026CF2CE4980>, 'Connection to api.telegram.org timed out. (connect timeout=10)'))
2025-09-08 16:46:00,678 - MainProcess - ERROR - Util tele bot check data - Failed to send message: HTTPSConnectionPool(host='api.telegram.org', port=443): Max retries exceeded with url: /bot7608728463:AAGqqSN5brGw5BX9ZzQ7eD2SOERtfzs6Ylo/sendMessage (Caused by ConnectTimeoutError(<urllib3.connection.HTTPSConnection object at 0x000001A761EE4980>, 'Connection to api.telegram.org timed out. (connect timeout=10)'))
2025-09-08 16:46:58,671 - MainProcess - ERROR - Util tele bot check data - Failed to send message: HTTPSConnectionPool(host='api.telegram.org', port=443): Max retries exceeded with url: /bot7608728463:AAGqqSN5brGw5BX9ZzQ7eD2SOERtfzs6Ylo/sendMessage (Caused by ConnectTimeoutError(<urllib3.connection.HTTPSConnection object at 0x000001D709C24980>, 'Connection to api.telegram.org timed out. (connect timeout=10)'))
